Workbook

Sheet 购销发票税收分类编码
A1: 序号 | B1: 一级分类 | C1: 二级分类 | D1: 商品和服务分类简称 | E1: 税收分类编码 | F1: 货物和劳务名称 | G1: 说明 | H1: 碳排放范围分类 | I1: 所属行业 | J1: 对应行业排放因子 | K1: 废弃物处置分类
A2: 1 | B2: 农、林、牧、渔业类产品 | C2: 农业产品 | D2: 谷物 | E2: 1010101010000000000 | F2: 稻谷 | G2: 包括早籼稻、晚籼稻、中籼稻、粳稻、糯稻、其他稻谷。 | H2: 范围3 | I2: =VLOOKUP(F2,[1]完整分类结果!$E:$G,3,0) -> 农、林、牧、渔及水利业 | J2: =VLOOKUP(I2,[2]行业排放因子!$A:$B,2,0) -> 90.746323 | K2: 农业固体废弃物（Agricultural Solid Waste）
A3: 2 | B3: 农、林、牧、渔业类产品 | C3: 农业产品 | D3: 谷物 | E3: 1010101020000000000 | F3: 小麦 | G3: 包括硬质小麦、软质小麦、其他小麦。 | H3: 范围3 | I3: =VLOOKUP(F3,[1]完整分类结果!$E:$G,3,0) -> 农、林、牧、渔及水利业 | J3: =VLOOKUP(I3,[2]行业排放因子!$A:$B,2,0) -> 90.746323 | K3: 农业固体废弃物（Agricultural Solid Waste）
A4: 3 | B4: 农、林、牧、渔业类产品 | C4: 农业产品 | D4: 谷物 | E4: 1010101030000000000 | F4: 玉米 | G4: 包括白玉米、黄玉米、糯玉米、甜玉米、其他玉米。 | H4: 范围3 | I4: =VLOOKUP(F4,[1]完整分类结果!$E:$G,3,0) -> 农、林、牧、渔及水利业 | J4: =VLOOKUP(I4,[2]行业排放因子!$A:$B,2,0) -> 90.746323 | K4: 农业固体废弃物（Agricultural Solid Waste）
A5: 4 | B5: 农、林、牧、渔业类产品 | C5: 农业产品 | D5: 谷物 | E5: 1010101040000000000 | F5: 谷子 | G5: 包括硬谷子、糯谷子、其他谷子。 | H5: 范围3 | I5: =VLOOKUP(F5,[1]完整分类结果!$E:$G,3,0) -> 农、林、牧、渔及水利业 | J5: =VLOOKUP(I5,[2]行业排放因子!$A:$B,2,0) -> 90.746323 | K5: 农业固体废弃物（Agricultural Solid Waste）
A6: 5 | B6: 农、林、牧、渔业类产品 | C6: 农业产品 | D6: 谷物 | E6: 1010101050000000000 | F6: 高粱 | G6: 包括红粒高粱、白粒高粱、糯高粱、其他高粱。 | H6: 范围3 | I6: =VLOOKUP(F6,[1]完整分类结果!$E:$G,3,0) -> 农、林、牧、渔及水利业 | J6: =VLOOKUP(I6,[2]行业排放因子!$A:$B,2,0) -> 90.746323 | K6: 农业固体废弃物（Agricultural Solid Waste）
A7: 6 | B7: 农、林、牧、渔业类产品 | C7: 农业产品 | D7: 谷物 | E7: 1010101060000000000 | F7: 大麦 | G7: 包括裸大麦、皮大麦。 | H7: 范围3 | I7: =VLOOKUP(F7,[1]完整分类结果!$E:$G,3,0) -> 农、林、牧、渔及水利业 | J7: =VLOOKUP(I7,[2]行业排放因子!$A:$B,2,0) -> 90.746323 | K7: 农业固体废弃物（Agricultural Solid Waste）
A8: 7 | B8: 农、林、牧、渔业类产品 | C8: 农业产品 | D8: 谷物 | E8: 1010101070000000000 | F8: 燕麦 | G8: 包括裸燕麦、皮燕麦。 | H8: 范围3 | I8: =VLOOKUP(F8,[1]完整分类结果!$E:$G,3,0) -> 农、林、牧、渔及水利业 | J8: =VLOOKUP(I8,[2]行业排放因子!$A:$B,2,0) -> 90.746323 | K8: 农业固体废弃物（Agricultural Solid Waste）
A9: 8 | B9: 农、林、牧、渔业类产品 | C9: 农业产品 | D9: 谷物 | E9: 1010101080000000000 | F9: 黑麦 | H9: 范围3 | I9: =VLOOKUP(F9,[1]完整分类结果!$E:$G,3,0) -> 农、林、牧、渔及水利业 | J9: =VLOOKUP(I9,[2]行业排放因子!$A:$B,2,0) -> 90.746323 | K9: 农业固体废弃物（Agricultural Solid Waste）
A10: 9 | B10: 农、林、牧、渔业类产品 | C10: 农业产品 | D10: 谷物 | E10: 1010101090000000000 | F10: 荞麦 | G10: 包括甜荞麦、苦荞麦。 | H10: 范围3 | I10: =VLOOKUP(F10,[1]完整分类结果!$E:$G,3,0) -> 农、林、牧、渔及水利业 | J10: =VLOOKUP(I10,[2]行业排放因子!$A:$B,2,0) -> 90.746323 | K10: 农业固体废弃物（Agricultural Solid Waste）
A11: 10 | B11: 农、林、牧、渔业类产品 | C11: 农业产品 | D11: 谷物 | E11: 1010101990000000000 | F11: 其他谷物 | G11: 包括糜子（硬糜子、糯糜子）、紫米、薏苡等。 | H11: 范围3 | I11: =VLOOKUP(F11,[1]完整分类结果!$E:$G,3,0) -> 农、林、牧、渔及水利业 | J11: =VLOOKUP(I11,[2]行业排放因子!$A:$B,2,0) -> 90.746323 | K11: 农业固体废弃物（Agricultural Solid Waste）
A12: 11 | B12: 农、林、牧、渔业类产品 | C12: 农业产品 | D12: 薯类 | E12: 1010102010000000000 | F12: 马铃薯 | G12: 又称土豆、山药蛋。 | H12: 范围3 | I12: =VLOOKUP(F12,[1]完整分类结果!$E:$G,3,0) -> 农、林、牧、渔及水利业 | J12: =VLOOKUP(I12,[2]行业排放因子!$A:$B,2,0) -> 90.746323 | K12: 农业固体废弃物（Agricultural Solid Waste）
A13: 12 | B13: 农、林、牧、渔业类产品 | C13: 农业产品 | D13: 薯类 | E13: 1010102020000000000 | F13: 木薯 | G13: 包括鲜木薯、木薯干、其他木薯。 | H13: 范围3 | I13: =VLOOKUP(F13,[1]完整分类结果!$E:$G,3,0) -> 农、林、牧、渔及水利业 | J13: =VLOOKUP(I13,[2]行业排放因子!$A:$B,2,0) -> 90.746323 | K13: 农业固体废弃物（Agricultural Solid Waste）
A14: 13 | B14: 农、林、牧、渔业类产品 | C14: 农业产品 | D14: 薯类 | E14: 1010102030000000000 | F14: 甘薯 | G14: 又称红薯、白薯、地瓜、番薯、包括甘薯干、其他鲜甘薯。 | H14: 范围3 | I14: =VLOOKUP(F14,[1]完整分类结果!$E:$G,3,0) -> 农、林、牧、渔及水利业 | J14: =VLOOKUP(I14,[2]行业排放因子!$A:$B,2,0) -> 90.746323 | K14: 农业固体废弃物（Agricultural Solid Waste）
A15: 14 | B15: 农、林、牧、渔业类产品 | C15: 农业产品 | D15: 薯类 | E15: 1010102990000000000 | F15: 其他薯类 | G15: 指其他未列明薯类。 | H15: 范围3 | I15: =VLOOKUP(F15,[1]完整分类结果!$E:$G,3,0) -> 农、林、牧、渔及水利业 | J15: =VLOOKUP(I15,[2]行业排放因子!$A:$B,2,0) -> 90.746323 | K15: 农业固体废弃物（Agricultural Solid Waste）
A16: 15 | B16: 农、林、牧、渔业类产品 | C16: 农业产品 | D16: 油料 | E16: 1010103010000000000 | F16: 花生 | G16: 包括带壳花生、花生仁。 | H16: 范围3 | I16: =VLOOKUP(F16,[1]完整分类结果!$E:$G,3,0) -> 农、林、牧、渔及水利业 | J16: =VLOOKUP(I16,[2]行业排放因子!$A:$B,2,0) -> 90.746323 | K16: 农业固体废弃物（Agricultural Solid Waste）
A17: 16 | B17: 农、林、牧、渔业类产品 | C17: 农业产品 | D17: 油料 | E17: 1010103020000000000 | F17: 油菜籽 | G17: 包括双低油菜籽（指低硫苷、低芥酸油菜籽）、其他油菜籽。 | H17: 范围3 | I17: =VLOOKUP(F17,[1]完整分类结果!$E:$G,3,0) -> 农、林、牧、渔及水利业 | J17: =VLOOKUP(I17,[2]行业排放因子!$A:$B,2,0) -> 90.746323 | K17: 农业固体废弃物（Agricultural Solid Waste）
A18: 17 | B18: 农、林、牧、渔业类产品 | C18: 农业产品 | D18: 油料 | E18: 1010103030000000000 | F18: 芝麻 | G18: 包括白芝麻、黑芝麻、黄芝麻。 | H18: 范围3 | I18: =VLOOKUP(F18,[1]完整分类结果!$E:$G,3,0) -> 农、林、牧、渔及水利业 | J18: =VLOOKUP(I18,[2]行业排放因子!$A:$B,2,0) -> 90.746323 | K18: 农业固体废弃物（Agricultural Solid Waste）
A19: 18 | B19: 农、林、牧、渔业类产品 | C19: 农业产品 | D19: 油料 | E19: 1010103990000000000 | F19: 其他油料 | G19: 其他含油子仁及果实，如胡麻籽、棉籽、蓖麻籽、芥子、红花籽、油棕果及油棕仁、罂粟子、油橄榄果、油茶籽（油料）等。 | H19: 范围3 | I19: =VLOOKUP(F19,[1]完整分类结果!$E:$G,3,0) -> 农、林、牧、渔及水利业 | J19: =VLOOKUP(I19,[2]行业排放因子!$A:$B,2,0) -> 90.746323 | K19: 农业固体废弃物（Agricultural Solid Waste）
A20: 19 | B20: 农、林、牧、渔业类产品 | C20: 农业产品 | D20: 干豆 | E20: 1010104010000000000 | F20: 大豆 | G20: 包括黄大豆、黑大豆、青大豆、褐红大豆、双青豆、青仁乌豆、小黑豆、其他大豆。 | H20: 范围3 | I20: =VLOOKUP(F20,[1]完整分类结果!$E:$G,3,0) -> 农、林、牧、渔及水利业 | J20: =VLOOKUP(I20,[2]行业排放因子!$A:$B,2,0) -> 90.746323 | K20: 农业固体废弃物（Agricultural Solid Waste）
A21: 20 | B21: 农、林、牧、渔业类产品 | C21: 农业产品 | D21: 干豆 | E21: 1010104020000000000 | F21: 绿豆 | G21: 包括明绿豆、毛绿豆。 | H21: 范围3 | I21: =VLOOKUP(F21,[1]完整分类结果!$E:$G,3,0) -> 农、林、牧、渔及水利业 | J21: =VLOOKUP(I21,[2]行业排放因子!$A:$B,2,0) -> 90.746323 | K21: 农业固体废弃物（Agricultural Solid Waste）
... A24: 23 | B24: 农、林、牧、渔业类产品 | C24: 农业产品 | D24: 生麻 | E24: 1010106000000000000 | F24: 生麻 | G24: 包括生亚麻、生苎麻、生黄红麻、生线麻、生苘麻、生大麻、生剑麻、其他生麻。 | H24: 范围3 | I24: =VLOOKUP(F24,[1]完整分类结果!$E:$G,3,0) -> 农、林、牧、渔及水利业 | J24: =VLOOKUP(I24,[2]行业排放因子!$A:$B,2,0) -> 90.746323 | K24: 农业固体废弃物（Agricultural Solid Waste）
A25: 24 | B25: 农、林、牧、渔业类产品 | C25: 农业产品 | D25: 糖料 | E25: 1010107010000000000 | F25: 甘蔗 | H25: 范围3 | I25: =VLOOKUP(F25,[1]完整分类结果!$E:$G,3,0) -> 农、林、牧、渔及水利业 | J25: =VLOOKUP(I25,[2]行业排放因子!$A:$B,2,0) -> 90.746323 | K25: 农业固体废弃物（Agricultural Solid Waste）
A26: 25 | B26: 农、林、牧、渔业类产品 | C26: 农业产品 | D26: 糖料 | E26: 1010107020000000000 | F26: 甜菜 | H26: 范围3 | I26: =VLOOKUP(F26,[1]完整分类结果!$E:$G,3,0) -> 农、林、牧、渔及水利业 | J26: =VLOOKUP(I26,[2]行业排放因子!$A:$B,2,0) -> 90.746323 | K26: 农业固体废弃物（Agricultural Solid Waste）
A27: 26 | B27: 农、林、牧、渔业类产品 | C27: 农业产品 | D27: 糖料 | E27: 1010107990000000000 | F27: 其他糖料 | H27: 范围3 | I27: =VLOOKUP(F27,[1]完整分类结果!$E:$G,3,0) -> 农、林、牧、渔及水利业 | J27: =VLOOKUP(I27,[2]行业排放因子!$A:$B,2,0) -> 90.746323 | K27: 农业固体废弃物（Agricultural Solid Waste）
A28: 27 | B28: 农、林、牧、渔业类产品 | C28: 农业产品 | D28: 烟草 | E28: 1010108010000000000 | F28: 未去梗烤烟叶 | G28: 指初烤未去梗烤烟叶，不包括复烤烟叶（详见1030401）。 | H28: 范围3 | I28: =VLOOKUP(F28,[1]完整分类结果!$E:$G,3,0) -> 农、林、牧、渔及水利业 | J28: =VLOOKUP(I28,[2]行业排放因子!$A:$B,2,0) -> 90.746323 | K28: 农业固体废弃物（Agricultural Solid Waste）
A29: 28 | B29: 农、林、牧、渔业类产品 | C29: 农业产品 | D29: 烟草 | E29: 1010108990000000000 | F29: 其他未加工烟草 | G29: 指其他未加工烟草，包括未去梗晒烟叶、未去梗晾烟叶、未去梗白肋烟、其他未加工烟草。 | H29: 范围3 | I29: =VLOOKUP(F29,[1]完整分类结果!$E:$G,3,0) -> 农、林、牧、渔及水利业 | J29: =VLOOKUP(I29,[2]行业排放因子!$A:$B,2,0) -> 90.746323 | K29: 农业固体废弃物（Agricultural Solid Waste）
A30: 29 | B30: 农、林、牧、渔业类产品 | C30: 农业产品 | D30: 饲料作物 | E30: 1010109010000000000 | F30: 饲料牧草 | G30: 包括苜蓿干草、羊草、沙打旺、其他饲料牧草。 | H30: 范围3 | I30: =VLOOKUP(F30,[1]完整分类结果!$E:$G,3,0) -> 农、林、牧、渔及水利业 | J30: =VLOOKUP(I30,[2]行业排放因子!$A:$B,2,0) -> 90.746323 | K30: 农业固体废弃物（Agricultural Solid Waste）
A31: 30 | B31: 农、林、牧、渔业类产品 | C31: 农业产品 | D31: 饲料作物 | E31: 1010109990000000000 | F31: 其他饲料作物 | G31: 包括青饲料、其他饲料作物。 | H31: 范围3 | I31: =VLOOKUP(F31,[1]完整分类结果!$E:$G,3,0) -> 农、林、牧、渔及水利业 | J31: =VLOOKUP(I31,[2]行业排放因子!$A:$B,2,0) -> 90.746323 | K31: 农业固体废弃物（Agricultural Solid Waste）
A32: 31 | B32: 农、林、牧、渔业类产品 | C32: 农业产品 | D32: 水生植物 | E32: 1010110000000000000 | F32: 水生植物类 | G32: 包括芦苇、席草、苇子、莲子、蒲草、慈姑、其他水生植物类。 | H32: 范围3 | I32: =VLOOKUP(F32,[1]完整分类结果!$E:$G,3,0) -> 农、林、牧、渔及水利业 | J32: =VLOOKUP(I32,[2]行业排放因子!$A:$B,2,0) -> 90.746323 | K32: 农业固体废弃物（Agricultural Solid Waste）
A33: 32 | B33: 农、林、牧、渔业类产品 | C33: 农业产品 | D33: 农副产品 | E33: 1010111010000000000 | F33: 作物茎、秆、根 | G33: 包括稻草、麦秸、谷壳、谷子秸、玉米秸、高粱秸、薯藤、大豆秸、花生蔓、油菜籽秆、芝麻秆、向日葵秆、棉花秆、麻秆、烟秆、其他作物茎、杆、根。 | H33: 范围3 | I33: =VLOOKUP(F33,[1]完整分类结果!$E:$G,3,0) -> 农、林、牧、渔及水利业 | J33: =VLOOKUP(I33,[2]行业排放因子!$A:$B,2,0) -> 90.746323 | K33: 农业固体废弃物（Agricultural Solid Waste）
A34: 33 | B34: 农、林、牧、渔业类产品 | C34: 农业产品 | D34: 农副产品 | E34: 1010111990000000000 | F34: 其他农作物副产品 | G34: 包括红黑瓜籽、园参籽等。 | H34: 范围3 | I34: =VLOOKUP(F34,[1]完整分类结果!$E:$G,3,0) -> 农、林、牧、渔及水利业 | J34: =VLOOKUP(I34,[2]行业排放因子!$A:$B,2,0) -> 90.746323 | K34: 农业固体废弃物（Agricultural Solid Waste）
A35: 34 | B35: 农、林、牧、渔业类产品 | C35: 农业产品 | D35: 蔬菜 | E35: 1010112010000000000 | F35: 萝卜等根菜类蔬菜 | G35: 包括萝卜（别名：葖、芦菔、莱菔）、胡萝卜（别名：红萝卜、黄萝卜、丁香萝卜、药性萝卜、番萝卜）、芜菁（别名：蔓菁、圆根、盘菜）、芜菁甘蓝（别名：洋蔓菁、洋疙瘩、洋大头菜）、根菾菜（别名：红菜头、紫菜头）、美洲防风（别名：欧防风芹菜萝卜、蒲芹萝卜）、牛蒡（别名：东洋萝卜、蝙蝠刺、大力子）、根芹菜（别名：根洋芹菜、球根塘蒿）、婆罗门参（别名：西洋牛蒡、蒜叶婆罗门参）、山葵）、黑婆罗门参（别名：菊牛蒡、鸦葱）。 | H35: 范围3 | I35: =VLOOKUP(F35,[1]完整分类结果!$E:$G,3,0) -> 农、林、牧、渔及水利业 | J35: =VLOOKUP(I35,[2]行业排放因子!$A:$B,2,0) -> 90.746323 | K35: 农业固体废弃物（Agricultural Solid Waste）
A36: 35 | B36: 农、林、牧、渔业类产品 | C36: 农业产品 | D36: 蔬菜 | E36: 1010112020000000000 | F36: 山药等薯芋类蔬菜 | G36: 包括姜（别名：生姜、黄姜）、芋（别名：芋头、芋艿、毛芋）、魔芋（别名：磨芋、蒟蒻）、山药（别名：薯蓣、白苕、脚板苕、山薯、大薯、佛掌薯）、豆薯（别名：地瓜、凉薯、沙葛、新罗葛）、葛、菊芋（别名：洋姜、鬼子姜）、菜用土圞儿（别名：香芋、美洲土圞儿）、蕉芋（别名：蕉藕、姜芋、食用美人蕉、食用莲蕉）、草石蚕（别名：螺丝菜、宝塔菜、甘露儿、地蚕）。不包括马铃薯（详见101010201）、甘薯（详见101010203）。 | H36: 范围3 | I36: =VLOOKUP(F36,[1]完整分类结果!$E:$G,3,0) -> 农、林、牧、渔及水利业 | J36: =VLOOKUP(I36,[2]行业排放因子!$A:$B,2,0) -> 90.746323 | K36: 农业固体废弃物（Agricultural Solid Waste）
A37: 36 | B37: 农、林、牧、渔业类产品 | C37: 农业产品 | D37: 蔬菜 | E37: 1010112030000000000 | F37: 葱蒜类蔬菜 | G37: 包括韭（别名：草钟乳、起阳草、懒人菜、韭黄）、大葱（别名：木葱、汉葱）、洋葱（别名：葱头、圆葱）、大蒜（别名：胡蒜、蒜）、蒜薹（别名：蒜苔）、蒜苗（别名：蒜黄、青蒜）、分葱（别名：四季葱、菜葱、冬葱）、胡葱（别名：蒜头葱、瓣子葱、火葱、肉葱）、细香葱（别名：四季葱、香葱、蝦夷葱）、韭葱（别名：扁葱、扁叶葱、洋蒜苗）、楼葱（别名：龙爪葱、龙角葱）、蕹（别名：藠头、藠子、莱芝）。 | H37: 范围3 | I37: =VLOOKUP(F37,[1]完整分类结果!$E:$G,3,0) -> 农、林、牧、渔及水利业 | J37: =VLOOKUP(I37,[2]行业排放因子!$A:$B,2,0) -> 90.746323 | K37: 农业固体废弃物（Agricultural Solid Waste）
A38: 37 | B38: 农、林、牧、渔业类产品 | C38: 农业产品 | D38: 蔬菜 | E38: 1010112040000000000 | F38: 白菜类蔬菜 | G38: 包括大白菜（别名：结球白菜、黄芽菜、包心白菜）、普通白菜（别名：白菜、小白菜、青菜、油菜）、乌塌菜（别名：榻菜、塌棵菜、榻地菘、黑菜）、菜薹（别名：菜心、绿菜薹、菜尖）、薹菜、紫菜薹（别名：红菜薹）。 | H38: 范围3 | I38: =VLOOKUP(F38,[1]完整分类结果!$E:$G,3,0) -> 农、林、牧、渔及水利业 | J38: =VLOOKUP(I38,[2]行业排放因子!$A:$B,2,0) -> 90.746323 | K38: 农业固体废弃物（Agricultural Solid Waste）
A39: 38 | B39: 农、林、牧、渔业类产品 | C39: 农业产品 | D39: 蔬菜 | E39: 1010112050000000000 | F39: 芥菜类蔬菜 | G39: 包括茎芥（别名：茎瘤芥、青菜头、菜头、包包菜、羊角菜、菱角菜、抱子芥、儿菜、娃娃菜、笋子芥、棒菜）、叶芥（别名：青菜、苦菜、春菜、辣菜、雪里蕻）、根芥（别名：辣疙瘩、冲菜、芥头、大头菜、疙瘩菜）、薹芥。 | H39: 范围3 | I39: =VLOOKUP(F39,[1]完整分类结果!$E:$G,3,0) -> 农、林、牧、渔及水利业 | J39: =VLOOKUP(I39,[2]行业排放因子!$A:$B,2,0) -> 90.746323 | K39: 农业固体废弃物（Agricultural Solid Waste）
... A48: 47 | B48: 农、林、牧、渔业类产品 | C48: 农业产品 | D48: 蔬菜 | E48: 1010112140000000000 | F48: 绿豆芽等芽苗菜 | G48: 包括绿豆芽（别名：绿豆芽幼芽）、黄豆芽（别名：黄豆幼芽）、黑豆芽（别名：黑豆幼芽）、青豆芽（别名：青豆幼芽）、红豆芽（别名：红豆幼芽）、蚕豆芽（别名：蚕豆幼芽）、红小豆苗（别名：红小豆幼芽）、豌豆苗（别名：豌豆幼芽）、花生芽（别名：花生幼芽）、苜蓿芽（别名：苜蓿幼芽或幼苗）、小扁豆芽（别名：小扁豆幼芽或幼苗）、萝卜芽（别名：萝卜芽幼苗）、菘蓝芽（别名：菘蓝幼芽或幼苗）、沙芥芽（别名：沙芥幼芽或幼苗）、芥菜芽（别名：芥菜幼芽或幼苗）、芥蓝芽（别名：芥蓝幼芽或幼苗）、白菜芽（别名：白菜幼芽或幼苗）、独行菜芽（别名：独行菜幼苗）、香椿苗（别名：香椿幼苗）、向日葵芽（别名：向日葵幼芽）、荞麦芽（别名：荞麦幼苗）、胡椒芽（别名：胡椒幼芽或幼苗）、紫苏芽（别名：紫苏幼芽或幼苗）、水芹芽（别名：水芹幼苗）、小麦苗（别名：小麦幼苗）、胡麻芽（别名：胡麻幼芽或幼苗）、蕹菜芽（别名：蕹菜幼苗）、芝麻芽（别名：芝麻幼芽或幼苗）、黄秋葵芽（别名：黄秋葵幼苗）、花椒脑（别名：花椒嫩芽）。 | H48: 范围3 | I48: =VLOOKUP(F48,[1]完整分类结果!$E:$G,3,0) -> 农、林、牧、渔及水利业 | J48: =VLOOKUP(I48,[2]行业排放因子!$A:$B,2,0) -> 90.746323 | K48: 农业固体废弃物（Agricultural Solid Waste）
A49: 48 | B49: 农、林、牧、渔业类产品 | C49: 农业产品 | D49: 蔬菜 | E49: 1010112150000000000 | F49: 其他蔬菜 | H49: 范围3 | I49: =VLOOKUP(F49,[1]完整分类结果!$E:$G,3,0) -> 农、林、牧、渔及水利业 | J49: =VLOOKUP(I49,[2]行业排放因子!$A:$B,2,0) -> 90.746323 | K49: 农业固体废弃物（Agricultural Solid Waste）
A50: 49 | B50: 农、林、牧、渔业类产品 | C50: 农业产品 | D50: 花卉 | E50: 1010113010000000000 | F50: 盆栽花 | G50: 包括鳞茎、块茎、块根、球茎、根颈及根茎等花卉。 | H50: 范围3 | I50: =VLOOKUP(F50,[1]完整分类结果!$E:$G,3,0) -> 农、林、牧、渔及水利业 | J50: =VLOOKUP(I50,[2]行业排放因子!$A:$B,2,0) -> 90.746323 | K50: 农业固体废弃物（Agricultural Solid Waste）
...

Sheet 服务发票税收分类编码
A1: 序号 | B1: 一级分类 | C1: 二级分类 | D1: 商品和服务分类简称 | E1: 税收分类编码 | F1: 货物和劳务名称 | G1: 说明 | H1: 碳排放范围分类 | I1: 所属行业 | J1: 对应行业排放因子
A2: 1 | B2: 劳务 | C2: 加工劳务 | D2: 劳务 | E2: 2010200000000000000 | F2: 垃圾处理、污泥处理处置劳务 | G2: 垃圾处理是指运用填埋、焚烧、综合处理和回收利用等形式，对垃圾进行减量化、资源化和无害化处理处置的业务。污泥处理处置是指对污水处理后产生的污泥进行稳定化、减量化和无害化处理处置的业务。 | H2: 范围3 | I2: =VLOOKUP(F2,[3]分类结果!$F:$G,2,0) -> 废品废料 | J2: =VLOOKUP(I2,[2]行业排放因子!$A:$B,2,0) -> 7.1376023
A3: 2 | B3: 劳务 | C3: 加工劳务 | D3: 劳务 | E3: 2010300000000000000 | F3: 污水处理劳务 | G3: 指将污水（包括城镇污水和工业废水）处理后达到《城镇污水处理厂污染物排放标准》（GB18918-2002），或达到相应的国家或地方水污染物排放标准中的直接排放限值的业务。其中，城镇污水是指城镇居民生活污水，机关、学校、医院、商业服务机构及各种公共设施排水，以及允许排入城镇污水收集系统的工业废水和初期雨水。工业废水是指工业生产过程中产生的，不允许排入城镇污水收集系统的废水和废液。 | H3: 范围3 | I3: =VLOOKUP(F3,[3]分类结果!$F:$G,2,0) -> 其他制造业 | J3: =VLOOKUP(I3,[2]行业排放因子!$A:$B,2,0) -> 0.24541556
A4: 3 | B4: 劳务 | C4: 加工劳务 | D4: 劳务 | E4: 2010400000000000000 | F4: 工业废气处理劳务 | G4: 指专门针对工业场所如工厂、车间产生的废气在对外排放前进行预处理，以达到国家废气对外排放标准的工作。 | H4: 范围3 | I4: =VLOOKUP(F4,[3]分类结果!$F:$G,2,0) -> 其他制造业 | J4: =VLOOKUP(I4,[2]行业排放因子!$A:$B,2,0) -> 0.24541556
A5: 4 | B5: 劳务 | C5: 加工劳务 | D5: 劳务 | E5: 2010500000000000000 | F5: 其他加工劳务 | G5: 指除稀土冶炼分离产品加工劳务、垃圾处理、污泥处理处置劳务、污水处理劳务、工业废气处理劳务以外的其他加工劳务。 | H5: 范围3 | I5: =VLOOKUP(F5,[3]分类结果!$F:$G,2,0) -> 其他制造业 | J5: =VLOOKUP(I5,[2]行业排放因子!$A:$B,2,0) -> 0.24541556
A6: 5 | B6: 劳务 | C6: 修理修配劳务 | D6: 劳务 | E6: 2020000000000000000 | F6: 修理修配劳务 | G6: 指受托对损伤和丧失功能的货物进行修复，使其恢复原状和功能的业务。 | H6: 范围3 | I6: =VLOOKUP(F6,[3]分类结果!$F:$G,2,0) -> 其他制造业 | J6: =VLOOKUP(I6,[2]行业排放因子!$A:$B,2,0) -> 0.24541556
A7: 6 | B7: 劳务 | C7: 其他劳务 | D7: 劳务 | E7: 2030000000000000000 | F7: 油气田企业为生产原油、天然气提供的生产性劳务 | G7: 生产性劳务是指油气田企业为生产原油、天然气，从地质普查、勘探开发到原油天然气销售的一系列生产过程所发生的劳务（具体见《增值税生产性劳务征税范围注释》）。 | H7: 范围3 | I7: =VLOOKUP(F7,[3]分类结果!$F:$G,2,0) -> 石油和天然气开采业 | J7: =VLOOKUP(I7,[2]行业排放因子!$A:$B,2,0) -> 44.014305
A8: 7 | B8: 劳务 | C8: 其他劳务 | D8: 劳务 | E8: 2040000000000000000 | F8: 矿产资源开采、挖掘、切割、破碎、分拣、洗选等劳务 | G8: 包括矿产资源开采、挖掘、切割、破碎、分拣、洗选等。 | H8: 范围3 | I8: =VLOOKUP(F8,[3]分类结果!$F:$G,2,0) -> 其他制造业 | J8: =VLOOKUP(I8,[2]行业排放因子!$A:$B,2,0) -> 0.24541556
A9: 8 | B9: 销售服务 | C9: 交通运输服务 | D9: 运输服务 | E9: 3010101010100000000 | F9: 国内铁路旅客运输服务 | G9: 指起运地和目的地都在境内的铁路旅客运输业务活动。 | H9: 范围3 | I9: =VLOOKUP(F9,[3]分类结果!$F:$G,2,0) -> 交通运输、仓储、邮电通信业 | J9: =VLOOKUP(I9,[2]行业排放因子!$A:$B,2,0) -> 667.48066
A10: 9 | B10: 销售服务 | C10: 交通运输服务 | D10: 运输服务 | E10: 3010101010200000000 | F10: 国际铁路旅客运输服务 | G10: 指通过铁路从境内载运旅客出境、从境外载运旅客入境，以及在境外载运旅客的运输业务活动。 | H10: 范围3 | I10: =VLOOKUP(F10,[3]分类结果!$F:$G,2,0) -> 交通运输、仓储、邮电通信业 | J10: =VLOOKUP(I10,[2]行业排放因子!$A:$B,2,0) -> 667.48066
A11: 10 | B11: 销售服务 | C11: 交通运输服务 | D11: 运输服务 | E11: 3010101010300000000 | F11: 港澳台铁路旅客运输服务 | G11: 指通过铁路往返香港、澳门、台湾，以及在香港、澳门、台湾提供的旅客运输业务活动。 | H11: 范围3 | I11: =VLOOKUP(F11,[3]分类结果!$F:$G,2,0) -> 交通运输、仓储、邮电通信业 | J11: =VLOOKUP(I11,[2]行业排放因子!$A:$B,2,0) -> 667.48066
A12: 11 | B12: 销售服务 | C12: 交通运输服务 | D12: 运输服务 | E12: 3010101020101010000 | F12: 国内长途汽车旅客运输服务 | G12: 指起运地和目的地都在境内的长途旅客运输业务活动，含长途班车服务。 | H12: 范围3 | I12: =VLOOKUP(F12,[3]分类结果!$F:$G,2,0) -> 交通运输设备制造业 | J12: =VLOOKUP(I12,[2]行业排放因子!$A:$B,2,0) -> 6.2441374
A13: 12 | B13: 销售服务 | C13: 交通运输服务 | D13: 运输服务 | E13: 3010101020101020000 | F13: 国际长途汽车旅客运输服务 | G13: 指通过道路从境内载运旅客出境、从境外载运旅客入境，以及在境外载运旅客的运输业务活动。 | H13: 范围3 | I13: =VLOOKUP(F13,[3]分类结果!$F:$G,2,0) -> 交通运输设备制造业 | J13: =VLOOKUP(I13,[2]行业排放因子!$A:$B,2,0) -> 6.2441374
... A18: 17 | B18: 销售服务 | C18: 交通运输服务 | D18: 运输服务 | E18: 3010101020203000000 | F18: 出租汽车客运服务 | G18: 指轿车出租计程、轿车出租包车、中型客车出租、大型客车出租客运业务活动，含城市班车服务。 | H18: 范围3 | I18: =VLOOKUP(F18,[3]分类结果!$F:$G,2,0) -> 交通运输设备制造业 | J18: =VLOOKUP(I18,[2]行业排放因子!$A:$B,2,0) -> 6.2441374
A19: 18 | B19: 销售服务 | C19: 交通运输服务 | D19: 运输服务 | E19: 3010101020204000000 | F19: 索道客运服务 | H19: 范围3 | I19: =VLOOKUP(F19,[3]分类结果!$F:$G,2,0) -> 其他制造业 | J19: =VLOOKUP(I19,[2]行业排放因子!$A:$B,2,0) -> 0.24541556
A20: 19 | B20: 销售服务 | C20: 交通运输服务 | D20: 运输服务 | E20: 3010101020299000000 | F20: 其他城市旅客公共交通服务 | G20: 指其他未列明的城市旅客运输活动。 | H20: 范围3 | I20: =VLOOKUP(F20,[3]分类结果!$F:$G,2,0) -> 交通运输、仓储、邮电通信业 | J20: =VLOOKUP(I20,[2]行业排放因子!$A:$B,2,0) -> 667.48066
A21: 20 | B21: 销售服务 | C21: 交通运输服务 | D21: 运输服务 | E21: 3010102010100000000 | F21: 国内铁路货物运输服务 | G21: 指起运地、目的地都在境内的铁路货物运输业务活动。 | H21: 范围3 | I21: =VLOOKUP(F21,[3]分类结果!$F:$G,2,0) -> 交通运输、仓储、邮电通信业 | J21: =VLOOKUP(I21,[2]行业排放因子!$A:$B,2,0) -> 667.48066
A22: 21 | B22: 销售服务 | C22: 交通运输服务 | D22: 运输服务 | E22: 3010102010200000000 | F22: 国际铁路货物运输服务 | G22: 指通过铁路从境内载运货物出境、从境外载运货物入境以及在境外载运货物的运输业务活动。 | H22: 范围3 | I22: =VLOOKUP(F22,[3]分类结果!$F:$G,2,0) -> 交通运输、仓储、邮电通信业 | J22: =VLOOKUP(I22,[2]行业排放因子!$A:$B,2,0) -> 667.48066
A23: 22 | B23: 销售服务 | C23: 交通运输服务 | D23: 运输服务 | E23: 3010102010300000000 | F23: 港澳台铁路货物运输服务 | G23: 指通过铁路往返香港、澳门、台湾以及在香港、澳门、台湾提供的货物运输业务活动。 | H23: 范围3 | I23: =VLOOKUP(F23,[3]分类结果!$F:$G,2,0) -> 交通运输、仓储、邮电通信业 | J23: =VLOOKUP(I23,[2]行业排放因子!$A:$B,2,0) -> 667.48066
A24: 23 | B24: 销售服务 | C24: 交通运输服务 | D24: 运输服务 | E24: 3010102020100000000 | F24: 国内道路货物运输服务 | G24: 指起运地、目的地都在境内的道路货物运输业务活动。 | H24: 范围3 | I24: =VLOOKUP(F24,[3]分类结果!$F:$G,2,0) -> 交通运输、仓储、邮电通信业 | J24: =VLOOKUP(I24,[2]行业排放因子!$A:$B,2,0) -> 667.48066
A25: 24 | B25: 销售服务 | C25: 交通运输服务 | D25: 运输服务 | E25: 3010102020200000000 | F25: 国际道路货物运输服务 | G25: 指通过道路从境内载运货物出境、从境外载运货物入境以及在境外载运货物的运输业务活动。 | H25: 范围3 | I25: =VLOOKUP(F25,[3]分类结果!$F:$G,2,0) -> 交通运输、仓储、邮电通信业 | J25: =VLOOKUP(I25,[2]行业排放因子!$A:$B,2,0) -> 667.48066
A26: 25 | B26: 销售服务 | C26: 交通运输服务 | D26: 运输服务 | E26: 3010102020300000000 | F26: 港澳台道路货物运输服务 | G26: 指通过道路往返香港、澳门、台湾以及在香港、澳门、台湾提供的货物运输业务活动。 | H26: 范围3 | I26: =VLOOKUP(F26,[3]分类结果!$F:$G,2,0) -> 交通运输、仓储、邮电通信业 | J26: =VLOOKUP(I26,[2]行业排放因子!$A:$B,2,0) -> 667.48066
A27: 26 | B27: 销售服务 | C27: 交通运输服务 | D27: 运输服务 | E27: 3010102990100000000 | F27: 国内其他陆路货物运输服务 | G27: 指起运地、目的地都在境内的其他陆路货物运输业务。 | H27: 范围3 | I27: =VLOOKUP(F27,[3]分类结果!$F:$G,2,0) -> 交通运输、仓储、邮电通信业 | J27: =VLOOKUP(I27,[2]行业排放因子!$A:$B,2,0) -> 667.48066
A28: 27 | B28: 销售服务 | C28: 交通运输服务 | D28: 运输服务 | E28: 3010102990200000000 | F28: 国际其他陆路货物运输服务 | G28: 指通过其他陆运方式从境内载运货物出境、从境外载运货物入境以及在境外载运货物的运输业务活动。 | H28: 范围3 | I28: =VLOOKUP(F28,[3]分类结果!$F:$G,2,0) -> 交通运输、仓储、邮电通信业 | J28: =VLOOKUP(I28,[2]行业排放因子!$A:$B,2,0) -> 667.48066
A29: 28 | B29: 销售服务 | C29: 交通运输服务 | D29: 运输服务 | E29: 3010102990300000000 | F29: 港澳台其他陆路货物运输服务 | G29: 指通过其他陆运方式往返香港、澳门、台湾以及在香港、澳门、台湾提供的货物运输业务活动。 | H29: 范围3 | I29: =VLOOKUP(F29,[3]分类结果!$F:$G,2,0) -> 交通运输、仓储、邮电通信业 | J29: =VLOOKUP(I29,[2]行业排放因子!$A:$B,2,0) -> 667.48066
A30: 29 | B30: 销售服务 | C30: 交通运输服务 | D30: 运输服务 | E30: 3010201010000000000 | F30: 国内水路旅客运输服务 | G30: 指起运地和目的地都在境内的水路旅客运输业务活动，含轮客渡服务。 | H30: 范围3 | I30: =VLOOKUP(F30,[3]分类结果!$F:$G,2,0) -> 交通运输、仓储、邮电通信业 | J30: =VLOOKUP(I30,[2]行业排放因子!$A:$B,2,0) -> 667.48066
A31: 30 | B31: 销售服务 | C31: 交通运输服务 | D31: 运输服务 | E31: 3010201020000000000 | F31: 国际水路旅客运输服务 | G31: 指通过水路运输方式在境内载运旅客出境、从境外载运旅客入境以及在境外载运旅客的运输业务活动。 | H31: 范围3 | I31: =VLOOKUP(F31,[3]分类结果!$F:$G,2,0) -> 交通运输、仓储、邮电通信业 | J31: =VLOOKUP(I31,[2]行业排放因子!$A:$B,2,0) -> 667.48066
... A70: 69 | B70: 销售服务 | C70: 交通运输服务 | D70: 运输服务 | E70: 3010506020000000000 | F70: 无运输工具承运货物联运运输服务 | G70: 指经营者以承运人身份与托运人签订货物联运运输服务合同，收取运费并承担承运人责任，然后委托实际承运人利用多种运输工具完成运输服务的经营活动。 | H70: 范围3 | I70: =VLOOKUP(F70,[3]分类结果!$F:$G,2,0) -> 交通运输、仓储、邮电通信业 | J70: =VLOOKUP(I70,[2]行业排放因子!$A:$B,2,0) -> 667.48066
A71: 70 | B71: 销售服务 | C71: 交通运输服务 | D71: 运输服务 | E71: 3010599010000000000 | F71: 其他无运输工具承运旅客运输业务 | H71: 范围3 | I71: =VLOOKUP(F71,[3]分类结果!$F:$G,2,0) -> 交通运输、仓储、邮电通信业 | J71: =VLOOKUP(I71,[2]行业排放因子!$A:$B,2,0) -> 667.48066
A72: 71 | B72: 销售服务 | C72: 交通运输服务 | D72: 运输服务 | E72: 3010599020000000000 | F72: 其他无运输工具承运货物运输业务 | H72: 范围3 | I72: =VLOOKUP(F72,[3]分类结果!$F:$G,2,0) -> 交通运输、仓储、邮电通信业 | J72: =VLOOKUP(I72,[2]行业排放因子!$A:$B,2,0) -> 667.48066
A73: 72 | B73: 销售服务 | C73: 交通运输服务 | D73: 运输服务 | E73: 3010601000000000000 | F73: 旅客联运服务 | G73: 指利用多种运输工具载运旅客的业务活动。 | H73: 范围3 | I73: =VLOOKUP(F73,[3]分类结果!$F:$G,2,0) -> 交通运输、仓储、邮电通信业 | J73: =VLOOKUP(I73,[2]行业排放因子!$A:$B,2,0) -> 667.48066
A74: 73 | B74: 销售服务 | C74: 交通运输服务 | D74: 运输服务 | E74: 3010602000000000000 | F74: 货物联运服务 | G74: 指利用多种运输工具载运货物的业务活动。 | H74: 范围3 | I74: =VLOOKUP(F74,[3]分类结果!$F:$G,2,0) -> 交通运输、仓储、邮电通信业 | J74: =VLOOKUP(I74,[2]行业排放因子!$A:$B,2,0) -> 667.48066
A75: 74 | B75: 销售服务 | C75: 交通运输服务 | D75: 运输服务 | E75: 3019901000000000000 | F75: 其他旅客运输服务 | H75: 范围3 | I75: =VLOOKUP(F75,[3]分类结果!$F:$G,2,0) -> 交通运输、仓储、邮电通信业 | J75: =VLOOKUP(I75,[2]行业排放因子!$A:$B,2,0) -> 667.48066
A76: 75 | B76: 销售服务 | C76: 交通运输服务 | D76: 运输服务 | E76: 3019902000000000000 | F76: 其他货物运输服务 | H76: 范围3 | I76: =VLOOKUP(F76,[3]分类结果!$F:$G,2,0) -> 交通运输、仓储、邮电通信业 | J76: =VLOOKUP(I76,[2]行业排放因子!$A:$B,2,0) -> 667.48066
A77: 76 | B77: 销售服务 | C77: 邮政服务 | D77: 邮政服务 | E77: 3020101010000000000 | F77: 函件寄递服务 | G77: 指信函、印刷品、邮资封片卡、无名址函件和邮政小包等的寄递服务业务。 | H77: 范围3 | I77: =VLOOKUP(F77,[3]分类结果!$F:$G,2,0) -> 印刷业、记录媒介复制业 | J77: =VLOOKUP(I77,[2]行业排放因子!$A:$B,2,0) -> 1.44956
A78: 77 | B78: 销售服务 | C78: 邮政服务 | D78: 邮政服务 | E78: 3020101020000000000 | F78: 包裹寄递服务 | G78: 指寄递包裹的业务，包裹是指按照封装上的名址递送给特定个人或者单位的独立封装的物品，其重量不超过五十千克，任何一边的尺寸不超过一百五十厘米，长、宽、高合计不超过三百厘米。 | H78: 范围3 | I78: =VLOOKUP(F78,[3]分类结果!$F:$G,2,0) -> 其他制造业 | J78: =VLOOKUP(I78,[2]行业排放因子!$A:$B,2,0) -> 0.24541556
A79: 78 | B79: 销售服务 | C79: 邮政服务 | D79: 邮政服务 | E79: 3020101990000000000 | F79: 其他邮件寄递服务 | G79: 指除函件、包裹以外的邮件寄递服务。 | H79: 范围3 | I79: =VLOOKUP(F79,[3]分类结果!$F:$G,2,0) -> 其他制造业 | J79: =VLOOKUP(I79,[2]行业排放因子!$A:$B,2,0) -> 0.24541556
A80: 79 | B80: 销售服务 | C80: 邮政服务 | D80: 邮政服务 | E80: 3020102000000000000 | F80: 邮票发行服务 | H80: 范围3 | I80: =VLOOKUP(F80,[3]分类结果!$F:$G,2,0) -> 其他制造业 | J80: =VLOOKUP(I80,[2]行业排放因子!$A:$B,2,0) -> 0.24541556
A81: 80 | B81: 销售服务 | C81: 邮政服务 | D81: 邮政服务 | E81: 3020103000000000000 | F81: 报刊发行服务 | H81: 范围3 | I81: =VLOOKUP(F81,[3]分类结果!$F:$G,2,0) -> 其他制造业 | J81: =VLOOKUP(I81,[2]行业排放因子!$A:$B,2,0) -> 0.24541556
A82: 81 | B82: 销售服务 | C82: 邮政服务 | D82: 邮政服务 | E82: 3020104000000000000 | F82: 邮政汇兑 | H82: 范围3 | I82: =VLOOKUP(F82,[3]分类结果!$F:$G,2,0) -> 交通运输、仓储、邮电通信业 | J82: =VLOOKUP(I82,[2]行业排放因子!$A:$B,2,0) -> 667.48066
...
